Workbook
Name UPDATE: 'Data Sheet'!$E$1

Sheet DCF>

Sheet WACC
B2: Weighted Average Cost of Capital
B4: All figures in INR unless stated otherwise.
B6: Peer comps
G7: Debt/ | H7: Debt/ | I7: Levered | J7: Unlevered
B8: Name of the Company | C8: Country | D8: Total Debt | E8: Total Equity | F8: Tax Rate 1 | G8: Equity | H8: Capital | I8: Beta 2 | J8: Beta 3
B9: Hind. Unilever | C9: India | D9: 1775 | E9: 546550.21 | F9: 0.25 | G9: =D9/E9 -> 0.0032476431 | H9: =D9/SUM(D9:E9) -> 0.00323713 | I9: 1.01 | J9: =I9/(1+(1-F9)*G9) -> 1.0075459
B10: ITC | C10: India | D10: 362.97 | E10: 416596.81 | F10: 0.25 | G10: =D10/E10 -> 0.00087127407 | H10: =D10/SUM(D10:E10) -> 0.00087051562 | I10: 0.64 | J10: =I10/(1+(1-F10)*G10) -> 0.63958206
B11: Nestle India | C11: India | D11: 476.85 | E11: 250989.48 | F11: 0.25 | G11: =D11/E11 -> 0.0018998804 | H11: =D11/SUM(D11:E11) -> 0.0018962777 | I11: 0.71 | J11: =I11/(1+(1-F11)*G11) -> 0.70898975
B12: Varun Beverages | C12: India | D12: 2508.19 | E12: 156135.31 | F12: 0.25 | G12: =D12/E12 -> 0.016064207 | H12: =D12/SUM(D12:E12) -> 0.015810229 | I12: 0.98 | J12: =I12/(1+(1-F12)*G12) -> 0.96833337
B13: Britannia Inds. | C13: India | D13: 2196.3 | E13: 148496.08 | F13: 0.25 | G13: =D13/E13 -> 0.014790289 | H13: =D13/SUM(D13:E13) -> 0.014574725 | I13: 0.81 | J13: =I13/(1+(1-F13)*G13) -> 0.80111347
E15: Average | F15: =AVERAGE(F9:F13) -> 0.25 | G15: =AVERAGE(G9:G13) -> 0.0073746589 | H15: =AVERAGE(H9:H13) -> 0.0072777754 | I15: =AVERAGE(I9:I13) -> 0.83 | J15: =AVERAGE(J9:J13) -> 0.82511291
E16: Median | F16: =MEDIAN(F9:F13) -> 0.25 | G16: =MEDIAN(G9:G12) -> 0.0025737617 | H16: =MEDIAN(H9:H12) -> 0.0025667039 | I16: =MEDIAN(I9:I12) -> 0.845 | J16: =MEDIAN(J9:J12) -> 0.83866156
B19: Cost of Debt | H19: Cost of Equity
B21: Pre-Tax Cost of Debt | E21: =88/1775 -> 0.049577465 | H21: Risk Free Return | K21: 0.0667
B22: Tax Rate | E22: 0.25 | H22: Equity Risk Premium | K22: =RM!G8-WACC!K21 -> 0.084792308
B23: Post Tax Cost of Debt | E23: =E21*(1-E22) -> 0.037183099 | H23: Levered Beta 4 | K23: =K32 -> 1.0467899
H24: Cost of Equity | K24: =K21+(K22*K23) -> 0.15545973
B27: Capital Structure | H27: Levered Beta
D29: Current | E29: Target | H29: Comps Median Unlevered Beta | K29: =J16 -> 0.83866156
B30: Total Debt | C30: =D9 -> 1775 | D30: =C30/$C$32 -> 0.00323713 | E30: =H15 -> 0.0072777754 | H30: Target Debt / Equtiy | K30: =E34 -> 0.0073311297
B31: Market Capitalization | C31: =E9 -> 546550.21 | D31: =C31/$C$32 -> 0.99676287 | E31: =E32-E30 -> 0.99272222 | H31: Tax Rate | K31: =E22 -> 0.25
B32: Total Capital | C32: =SUM(C30:C31) -> 548325.21 | D32: =C32/$C$32 -> 1 | E32: 1 | H32: Levered Beta | K32: =K29*(1+(1-K30)*K31) -> 1.0467899
B34: Debt/Equity | D34: =D30/D31 -> 0.0032476431 | E34: =E30/E31 -> 0.0073311297 | H34: Weighted Average Cost of Capital
H36: Cost of Equity | K36: =K24 -> 0.15545973
H37: Equity Weight | K37: =E31 -> 0.99272222
H39: Cost of Debt | K39: =E23 -> 0.037183099
H40: Debt Weight | K40: =E30 -> 0.0072777754
H42: WACC | K42: =(K36*K37)+(K39*K40) -> 0.15459894

Sheet Data>

Sheet Beta - Regression
B2: Regression Beta
B5: Hul Monthy Returns | F5: Nifty Monthly Returns
B7: Date | C7: Closing Price | D7: Return | F7: Closing Price | G7: Return | I7: Beta 1 | J7: =SLOPE(D9:D68,G9:G68) -> 0.96595873
B9: 44197 | C9: 2128.83 | F9: 13634.6
B10: 44198 | C10: 2004.85 | D10: =C10/C9-1 -> -0.058238563 | F10: 14529.15 | G10: =F10/F9-1 -> 0.065608819
B11: 44199 | C11: 2286.42 | D11: =C11/C10-1 -> 0.14044442 | F11: 14690.7 | G11: =F11/F10-1 -> 0.011119026
B12: 44200 | C12: 2213.32 | D12: =C12/C11-1 -> -0.031971379 | F12: 14631.1 | G12: =F12/F11-1 -> -0.0040569884 | I12: SUMMARY OUTPUT
B13: 44201 | C13: 2200.44 | D13: =C13/C12-1 -> -0.0058193122 | F13: 15582.8 | G13: =F13/F12-1 -> 0.065046374
B14: 44202 | C14: 2340.67 | D14: =C14/C13-1 -> 0.063728163 | F14: 15721.5 | G14: =F14/F13-1 -> 0.0089008394 | I14: Regression Statistics
B15: 44203 | C15: 2209.96 | D15: =C15/C14-1 -> -0.055842985 | F15: 15763.05 | G15: =F15/F14-1 -> 0.0026428776 | I15: Multiple R | J15: 0.59361328
B16: 44204 | C16: 2580.11 | D16: =C16/C15-1 -> 0.16749172 | F16: 17132.2 | G16: =F16/F15-1 -> 0.086858191 | I16: R Square | J16: 0.35237672
B17: 44205 | C17: 2558.98 | D17: =C17/C16-1 -> -0.0081895733 | F17: 17618.15 | G17: =F17/F16-1 -> 0.028364717 | I17: Adjusted R Square | J17: 0.34101491
B18: 44206 | C18: 2280.58 | D18: =C18/C17-1 -> -0.10879335 | F18: 17671.65 | G18: =F18/F17-1 -> 0.0030366412 | I18: Standard Error | J18: 0.049497345
B19: 44207 | C19: 2208.54 | D19: =C19/C18-1 -> -0.031588456 | F19: 16983.2 | G19: =F19/F18-1 -> -0.038957879 | I19: Observations | J19: 59
B20: 44208 | C20: 2249.14 | D20: =C20/C19-1 -> 0.018383185 | F20: 17354.05 | G20: =F20/F19-1 -> 0.021836285
B21: 44562 | C21: 2380 | D21: =C21/C20-1 -> 0.058182239 | F21: 17339.85 | G21: =F21/F20-1 -> -0.0008182528 | I21: ANOVA
B22: 44563 | C22: 2310 | D22: =C22/C21-1 -> -0.029411765 | F22: 16793.9 | G22: =F22/F21-1 -> -0.031485278 | J22: df | K22: SS | L22: MS | M22: F | N22: Significance F
B23: 44564 | C23: 2215 | D23: =C23/C22-1 -> -0.041125541 | F23: 17464.75 | G23: =F23/F22-1 -> 0.039946052 | I23: Regression | J23: 1 | K23: 0.075984224 | L23: 0.075984224 | M23: 31.014131 | N23: 7.2218178e-07
B24: 44565 | C24: 2285 | D24: =C24/C23-1 -> 0.031602709 | F24: 17102.55 | G24: =F24/F23-1 -> -0.020738917 | I24: Residual | J24: 57 | K24: 0.13964927 | L24: 0.0024499872
B25: 44566 | C25: 2260 | D25: =C25/C24-1 -> -0.010940919 | F25: 16584.55 | G25: =F25/F24-1 -> -0.030287881 | I25: Total | J25: 58 | K25: 0.21563349
B26: 44567 | C26: 2170 | D26: =C26/C25-1 -> -0.039823009 | F26: 15780.25 | G26: =F26/F25-1 -> -0.048496944
B27: 44568 | C27: 2560 | D27: =C27/C26-1 -> 0.1797235 | F27: 17158.25 | G27: =F27/F26-1 -> 0.087324345 | J27: Coefficients | K27: Standard Error | L27: t Stat | M27: P-value | N27: Lower 95% | O27: Upper 95% | P27: Lower 95.0% | Q27: Upper 95.0%
B28: 44569 | C28: 2655 | D28: =C28/C27-1 -> 0.037109375 | F28: 17759.3 | G28: =F28/F27-1 -> 0.035029796 | I28: Intercept | J28: -0.0075633114 | K28: 0.0067836821 | L28: -1.1149272 | M28: 0.26956047 | N28: -0.0211474 | O28: 0.0060207777 | P28: -0.0211474 | Q28: 0.0060207777
B29: 44570 | C29: 2575 | D29: =C29/C28-1 -> -0.030131827 | F29: 17094.35 | G29: =F29/F28-1 -> -0.037442354 | I29: X Variable 1 | J29: 1.0079258 | K29: 0.18098757 | L29: 5.5690332 | M29: 7.2218178e-07 | N29: 0.64550444 | O29: 1.3703472 | P29: 0.64550444 | Q29: 1.3703472
B30: 44571 | C30: 2590 | D30: =C30/C29-1 -> 0.0058252427 | F30: 18012.2 | G30: =F30/F29-1 -> 0.053693179
B31: 44572 | C31: 2680 | D31: =C31/C30-1 -> 0.034749035 | F31: 18758.35 | G31: =F31/F30-1 -> 0.041424701
B32: 44573 | C32: 2559 | D32: =C32/C31-1 -> -0.045149254 | F32: 18105.3 | G32: =F32/F31-1 -> -0.03481383
B33: 44927 | C33: 2585 | D33: =C33/C32-1 -> 0.010160219 | F33: 17662 | G33: =F33/F32-1 -> -0.024484543
B34: 44928 | C34: 2490 | D34: =C34/C33-1 -> -0.036750484 | F34: 17303 | G34: =F34/F33-1 -> -0.020326124
B35: 44929 | C35: 2480 | D35: =C35/C34-1 -> -0.0040160643 | F35: 17359 | G35: =F35/F34-1 -> 0.003236433
B36: 44930 | C36: 2455 | D36: =C36/C35-1 -> -0.010080645 | F36: 18065 | G36: =F36/F35-1 -> 0.040670546
B37: 44931 | C37: 2525 | D37: =C37/C36-1 -> 0.028513238 | F37: 18534 | G37: =F37/F36-1 -> 0.025961805
B38: 44932 | C38: 2580 | D38: =C38/C37-1 -> 0.021782178 | F38: 19189 | G38: =F38/F37-1 -> 0.035340455
B39: 44933 | C39: 2650 | D39: =C39/C38-1 -> 0.027131783 | F39: 19753 | G39: =F39/F38-1 -> 0.029391839
B40: 44934 | C40: 2685 | D40: =C40/C39-1 -> 0.013207547 | F40: 19254 | G40: =F40/F39-1 -> -0.025261986
B41: 44935 | C41: 2665 | D41: =C41/C40-1 -> -0.0074487896 | F41: 19638 | G41: =F41/F40-1 -> 0.019943908
... B68: 45669 | C68: 2315.9 | D68: =C68/C67-1 -> -0.045513182 | F68: 26129 | G68: =F68/F67-1 -> 0.003764742

Sheet Beta - Comps
B3: S.NO | C3: NAME | D3: CMP | E3: DEBT/EQ | F3: MAR CAP | G3: DEBT
B4: 1 | C4: Hind. Unilever | D4: 2326 | E4: 0.04 | F4: 546550.21 | G4: 1775
B5: 2 | C5: ITC | D5: 332.5 | E5: 0.01 | F5: 416596.81 | G5: 362.97
B6: 3 | C6: Nestle India | D6: 1301.55 | E6: 0.1 | F6: 250989.48 | G6: 476.85
B7: 4 | C7: Varun Beverages | D7: 461.45 | E7: 0.13 | F7: 156135.31 | G7: 2508.19
B8: 5 | C8: Britannia Inds. | D8: 6167.3 | E8: 0.59 | F8: 148496.08 | G8: 2196.3

Sheet RM
B2: Return on Markets
B4: Year | C4: Annual
B5: 2000 | C5: -0.1465
B6: 2001 | C6: -0.1618 | E6: Average Return | G6: =AVERAGE(C5:C30) -> 0.15149231
B7: 2002 | C7: 0.0325 | E7: Dividend Yield | G7: 1.28% 1
B8: 2003 | C8: 0.719 | E8: Total Market Return | G8: =SUM(G6:G7) -> 0.15149231
B9: 2004 | C9: 0.1068
B10: 2005 | C10: 0.3634
B11: 2006 | C11: 0.3983
B12: 2007 | C12: 0.5477
B13: 2008 | C13: -0.5179
B14: 2009 | C14: 0.7576
B15: 2010 | C15: 0.1795
B16: 2011 | C16: -0.2462
B17: 2012 | C17: 0.277
B18: 2013 | C18: 0.0676
B19: 2014 | C19: 0.3139
B20: 2015 | C20: -0.0406
... B30: 2025 | C30: 0.1051

Sheet Intrinsic Growth
B2: Calculation ROIC | F2: ='[1]Raw FS'!J3 -> 44256 | G2: ='[1]Raw FS'!K3 -> 44621 | H2: ='[1]Raw FS'!L3 -> 44986 | I2: ='[1]Raw FS'!M3 -> 45352 | J2: ='[1]Raw FS'!N3 -> 45717
B4: Current Assets
B5: Inventories | F5: ='[1]Raw FS'!J33 -> 3579 | G5: ='[1]Raw FS'!K33 -> 4096 | H5: ='[1]Raw FS'!L33 -> 4251 | I5: ='[1]Raw FS'!M33 -> 4022 | J5: ='[1]Raw FS'!N33 -> 4415
B6: Trade receivables | F6: ='[1]Raw FS'!J34 -> 1758 | G6: ='[1]Raw FS'!K34 -> 2236 | H6: ='[1]Raw FS'!L34 -> 3079 | I6: ='[1]Raw FS'!M34 -> 2997 | J6: ='[1]Raw FS'!N34 -> 3819
B7: Loans n Advances | F7: ='[1]Raw FS'!J36 -> 78 | G7: ='[1]Raw FS'!K36 -> 170 | H7: ='[1]Raw FS'!L36 -> 188 | I7: ='[1]Raw FS'!M36 -> 172 | J7: ='[1]Raw FS'!N36 -> 242
B8: Other asset items | F8: ='[1]Raw FS'!J37 -> 3957 | G8: ='[1]Raw FS'!K37 -> 3851 | H8: ='[1]Raw FS'!L37 -> 4189 | I8: ='[1]Raw FS'!M37 -> 4345 | J8: ='[1]Raw FS'!N37 -> 4679
B9: Total Current Assets | F9: =SUM(F5:F8) -> 9372 | G9: =SUM(G5:G8) -> 10353 | H9: =SUM(H5:H8) -> 11707 | I9: =SUM(I5:I8) -> 11536 | J9: =SUM(J5:J8) -> 13155
B11: Current Liabilites
B12: Trade Payables | F12: ='[1]Raw FS'!J13 -> 8802 | G12: ='[1]Raw FS'!K13 -> 9068 | H12: ='[1]Raw FS'!L13 -> 9574 | I12: ='[1]Raw FS'!M13 -> 10486 | J12: ='[1]Raw FS'!N13 -> 11315
B13: Advance from Customers | F13: ='[1]Raw FS'!J14 -> 96 | G13: ='[1]Raw FS'!K14 -> 119 | H13: ='[1]Raw FS'!L14 -> 98 | I13: ='[1]Raw FS'!M14 -> 91 | J13: ='[1]Raw FS'!N14 -> 105
B14: Other liability items | F14: ='[1]Raw FS'!J15 -> 12148 | G14: ='[1]Raw FS'!K15 -> 11189 | H14: ='[1]Raw FS'!L15 -> 11664 | I14: ='[1]Raw FS'!M15 -> 15005 | J14: ='[1]Raw FS'!N15 -> 17186
B15: Total Current Liabilities | F15: =SUM(F12:F14) -> 21046 | G15: =SUM(G12:G14) -> 20376 | H15: =SUM(H12:H14) -> 21336 | I15: =SUM(I12:I14) -> 25582 | J15: =SUM(J12:J14) -> 28606
B17: Net Working Capital | F17: =F9-F15 -> -11674 | G17: =G9-G15 -> -10023 | H17: =H9-H15 -> -9629 | I17: =I9-I15 -> -14046 | J17: =J9-J15 -> -15451
B20: Non Current Assets
B21: ='[1]Raw FS'!B19 -> Land | F21: ='[1]Raw FS'!J19 -> 477 | G21: ='[1]Raw FS'!K19 -> 477 | H21: ='[1]Raw FS'!L19 -> 609 | I21: ='[1]Raw FS'!M19 -> 633 | J21: ='[1]Raw FS'!N19 -> 628
B22: ='[1]Raw FS'!B20 -> Building | F22: ='[1]Raw FS'!J20 -> 2602 | G22: ='[1]Raw FS'!K20 -> 2788 | H22: ='[1]Raw FS'!L20 -> 3101 | I22: ='[1]Raw FS'!M20 -> 3590 | J22: ='[1]Raw FS'!N20 -> 3833
B23: ='[1]Raw FS'!B21 -> Plant Machinery | F23: ='[1]Raw FS'!J21 -> 6097 | G23: ='[1]Raw FS'!K21 -> 6566 | H23: ='[1]Raw FS'!L21 -> 7612 | I23: ='[1]Raw FS'!M21 -> 8946 | J23: ='[1]Raw FS'!N21 -> 9900
B24: ='[1]Raw FS'!B22 -> Equipments | F24: ='[1]Raw FS'!J22 -> 175 | G24: ='[1]Raw FS'!K22 -> 181 | H24: ='[1]Raw FS'!L22 -> 185 | I24: ='[1]Raw FS'!M22 -> 206 | J24: ='[1]Raw FS'!N22 -> 245
B25: ='[1]Raw FS'!B23 -> Furniture n fittings | F25: ='[1]Raw FS'!J23 -> 156 | G25: ='[1]Raw FS'!K23 -> 152 | H25: ='[1]Raw FS'!L23 -> 161 | I25: ='[1]Raw FS'!M23 -> 165 | J25: ='[1]Raw FS'!N23 -> 174
B26: ='[1]Raw FS'!B24 -> Vehicles | F26: ='[1]Raw FS'!J24 -> 0 | G26: ='[1]Raw FS'!K24 -> 0 | H26: ='[1]Raw FS'!L24 -> 33 | I26: ='[1]Raw FS'!M24 -> 39 | J26: ='[1]Raw FS'!N24 -> 102
B27: ='[1]Raw FS'!B25 -> Intangible Assets | F27: ='[1]Raw FS'!J25 -> 45262 | G27: ='[1]Raw FS'!K25 -> 45262 | H27: ='[1]Raw FS'!L25 -> 45692 | I27: ='[1]Raw FS'!M25 -> 45692 | J27: ='[1]Raw FS'!N25 -> 45692
B28: ='[1]Raw FS'!B26 -> Other fixed assets | F28: ='[1]Raw FS'!J26 -> 155 | G28: ='[1]Raw FS'!K26 -> 152 | H28: ='[1]Raw FS'!L26 -> 171 | I28: ='[1]Raw FS'!M26 -> 180 | J28: ='[1]Raw FS'!N26 -> 190
B29: ='[1]Raw FS'!B27 -> Gross Block | F29: =SUM(F21:F28) -> 54924 | G29: =SUM(G21:G28) -> 55578 | H29: =SUM(H21:H28) -> 57564 | I29: =SUM(I21:I28) -> 59451 | J29: =SUM(J21:J28) -> 60764
B30: Accumalated Depreciation | F30: =-'[1]Raw FS'!J28 -> -3481 | G30: =-'[1]Raw FS'!K28 -> -4105 | H30: =-'[1]Raw FS'!L28 -> -4886 | I30: =-'[1]Raw FS'!M28 -> -5707 | J30: =-'[1]Raw FS'!N28 -> -6429
B31: Net Non Current Assets | F31: =SUM(F29:F30) -> 51443 | G31: =SUM(G29:G30) -> 51473 | H31: =SUM(H29:H30) -> 52678 | I31: =SUM(I29:I30) -> 53744 | J31: =SUM(J29:J30) -> 54335
B33: Invested Capital | F33: =F31+F17 -> 39769 | G33: =G31+G17 -> 41450 | H33: =H31+H17 -> 43049 | I33: =I31+I17 -> 39698 | J33: =J31+J17 -> 38884
B34: EBIT | F34: ='Historical FS'!$H$26+'Historical FS'!$H$20 -> 10552 | G34: ='Historical FS'!$I$26+'Historical FS'!$I$20 -> 11766 | H34: ='Historical FS'!$J$26+'Historical FS'!$J$20 -> 13010 | I34: ='Historical FS'!$K$26+'Historical FS'!$K$20 -> 13443 | J34: ='Historical FS'!$L$26+'Historical FS'!$L$20 -> 13488
B36: ROIC | F36: =F34*(1-F48)/F33 -> 0.19899922 | G36: =G34*(1-G48)/G33 -> 0.21289505 | H36: =H34*(1-H48)/H33 -> 0.22666032 | I36: =I34*(1-I48)/I33 -> 0.25397375 | J36: =J34*(1-J48)/J33 -> 0.26015842
I38: 4 Year Average | J38: =AVERAGE(G36:J36) -> 0.23842189
I39: 4 Year Median | J39: =MEDIAN(G36:J36) -> 0.24031703
B42: Calculation of Reinvestment Rate | F42: 44256 | G42: 44621 | H42: 44986 | I42: 45352 | J42: 45717
B44: Net Capex | F44: =-SUM('Raw FS'!J54:J55) -> 4066 | G44: =-SUM('Raw FS'!K54:K55) -> 1053 | H44: =-SUM('Raw FS'!L54:L55) -> 1011 | I44: =-SUM('Raw FS'!M54:M55) -> 1457 | J44: =-SUM('Raw FS'!N54:N55) -> 1262
B45: Change in Working Capital | G45: =G17-F17 -> 1651 | H45: =H17-G17 -> 394 | I45: =I17-H17 -> -4417 | J45: =J17-I17 -> -1405
B47: EBIT | F47: =F34 -> 10552 | G47: =G34 -> 11766 | H47: =H34 -> 13010 | I47: =I34 -> 13443 | J47: =J34 -> 13488
B48: Marginal Tax | F48: 0.25 | G48: 0.25 | H48: 0.25 | I48: 0.25 | J48: 0.25
B49: EBIT (1-T) | F49: =F47*(1-F48) -> 7914 | G49: =G47*(1-G48) -> 8824.5 | H49: =H47*(1-H48) -> 9757.5 | I49: =I47*(1-I48) -> 10082.25 | J49: =J47*(1-J48) -> 10116
B51: Reinvestment | G51: =SUM(G44:G45) -> 2704 | H51: =SUM(H44:H45) -> 1405 | I51: =SUM(I44:I45) -> -2960 | J51: =SUM(J44:J45) -> -143
B53: Reinvestment Rate | G53: =G51/G49 -> 0.30641963 | H53: =H51/H49 -> 0.1439918 | I53: =I51/I49 -> -0.29358526 | J53: =J51/J49 -> -0.014136022
I55: 4 Year Average | J55: =AVERAGE(G53:J53) -> 0.035672536
I56: 4 Year Median | J56: =MEDIAN(G53:J53) -> 0.06492789
...

Sheet DCF
B2: All figures in INR Crores unless stated otherwise.
B4: Calculation of PV of FCFF | F4: 45717 | G4: =EDATE(F4,12) -> 46082 | H4: =EDATE(G4,12) -> 46447 | I4: =EDATE(H4,12) -> 46813 | J4: =EDATE(I4,12) -> 47178 | K4: =EDATE(J4,12) -> 47543
B6: EBIT | F6: ='Intrinsic Growth'!J34 -> 13488 | G6: =F6*(1+$F$16) -> 13554.199 | H6: =G6*(1+$F$16) -> 13620.722 | I6: =H6*(1+$F$16) -> 13687.573 | J6: =I6*(1+$F$16) -> 13754.751 | K6: =J6*(1+$F$16) -> 13822.259
B7: Tax Rate | F7: 0.25 | G7: =F7 -> 0.25 | H7: =G7 -> 0.25 | I7: =H7 -> 0.25 | J7: =I7 -> 0.25 | K7: =J7 -> 0.25
B8: EBIT(1-T) | F8: =F6*(1-F7) -> 10116 | G8: =G6*(1-G7) -> 10165.649 | H8: =H6*(1-H7) -> 10215.542 | I8: =I6*(1-I7) -> 10265.679 | J8: =J6*(1-J7) -> 10316.063 | K8: =K6*(1-K7) -> 10366.694
B9: Less: Reinvestment Rate | G9: ='Intrinsic Growth'!$J$55 -> 0.035672536 | H9: ='Intrinsic Growth'!$J$55 -> 0.035672536 | I9: ='Intrinsic Growth'!$J$55 -> 0.035672536 | J9: ='Intrinsic Growth'!$J$55 -> 0.035672536 | K9: ='Intrinsic Growth'!$J$55 -> 0.035672536
B10: Free Cash Flow to Firm (FCFF) | F10: =F8*(1-F9) -> 10116 | G10: =G8*(1-G9) -> 9803.0146 | H10: =H8*(1-H9) -> 9851.1275 | I10: =I8*(1-I9) -> 9899.4766 | J10: =J8*(1-J9) -> 9948.063 | K10: =K8*(1-K9) -> 9996.8878
B11: Mid Year Convention | G11: 0.5 | H11: =G11+1 -> 1.5 | I11: =H11+1 -> 2.5 | J11: =I11+1 -> 3.5 | K11: =J11+1 -> 4.5
B12: Discounting Factor | G12: =1/(1+$F$18)^G11 -> 0.9306458 | H12: =1/(1+$F$18)^H11 -> 0.80603383 | I12: =1/(1+$F$18)^I11 -> 0.6981072 | J12: =1/(1+$F$18)^J11 -> 0.60463177 | K12: =1/(1+$F$18)^K11 -> 0.52367255
B14: PV of FCFF | G14: =G10*G12 -> 9123.1344 | H14: =H10*H12 -> 7940.342 | I14: =I10*I12 -> 6910.8959 | J14: =J10*J12 -> 6014.9149 | K14: =K10*K12 -> 5235.0957
B16: Expected Growth | F16: ='Intrinsic Growth'!J65 -> 0.0049079738
B17: Terminal Growth | F17: 0.04
B18: WACC | F18: =WACC!K42 -> 0.15459894
B20: Calculation of Terminal Value | I20: Sensitivity Analysis
H21: =D26 -> 90723.034 | I21: 0.1387 | J21: 0.1436 | K21: 0.1546 | L21: 0.1698 | M21: 0.1773
B22: FCFF(n+1) | D22: =K10*(1+F17) -> 10396.763 | H22: 0.03 | I22: 95646.397 | J22: 91520.804 | K22: 83441.118 | L22: 74368.836 | M22: 70582.236
B23: WACC | D23: =F18 -> 0.15459894 | H23: 0.04 | I23: 105337.01 | J23: 100354.86 | K23: 90722.193 | L23: 80098.331 | M23: 75722.967
B24: Terminal Growth Rate | D24: =F17 -> 0.04 | H24: 0.05 | I24: 117212.66 | J24: 111076.53 | K24: 99395.443 | L24: 86784.335 | M24: 81671.354
H25: 0.06 | I25: 132106.27 | J25: 124363.2 | K25: 109902.36 | L25: 94688.19 | M25: 88633.958
B26: Terminal Value | D26: =D22/(D23-D24) -> 90723.034 | H26: 0.07 | I26: 151335.71 | J26: 141260.37 | K26: 122893.18 | L26: 104175.99 | M26: 96894.346
B28: Calculation of Equity Value Per Share
B30: PV of FCFF | D30: =SUM(G14:K14) -> 35224.383
B31: PV of Terminal Value | D31: =D26*K12 -> 47509.162
B32: Value of Operating Assets | D32: =SUM(D30:D31) -> 82733.545
B34: Add:Cash | D34: ='Data Sheet'!$K$69 -> 4442
B35: Less:Debt | D35: =SUM('Raw FS'!N8:N9) -> 1648
B36: Value of Equity | D36: =D32+D34-D35 -> 85527.545
B37: No. of Shares | D37: ='Data Sheet'!$B$6 -> 234.95911
B39: Equity Value Per Share | D39: =D36/D37 -> 364.01034

Sheet Data Sheet
A1: COMPANY NAME | B1: HINDUSTAN UNILEVER LTD | E1: =IF(B2<>B3, "A NEW VERSION OF THE WORKSHEET IS AVAILABLE", "")
A2: LATEST VERSION | B2: 2.1 | E2: PLEASE DO NOT MAKE ANY CHANGES TO THIS SHEET
A3: CURRENT VERSION | B3: 2.1
A5: META
A6: Number of shares | B6: =IF(B9>0, B9/B8, 0) -> 234.95911
A7: Face Value | B7: 1
A8: Current Price | B8: 2462.4
A9: Market Capitalization | B9: 578563.31
A15: PROFIT & LOSS
A16: Report Date | B16: 42460 | C16: 42825 | D16: 43190 | E16: 43555 | F16: 43921 | G16: 44286 | H16: 44651 | I16: 45016 | J16: 45382 | K16: 45747
A17: Sales | B17: 32186 | C17: 33162 | D17: 35545 | E17: 39310 | F17: 39783 | G17: 47028 | H17: 52446 | I17: 60580 | J17: 61896 | K17: 63121
A18: Raw Material Cost | B18: 13184 | C18: 13606 | D18: 14233 | E18: 15845 | F18: 15697 | G18: 20141 | H18: 22871 | I18: 28427 | J18: 26822 | K18: 27344
A19: Change in Inventory | B19: -83 | C19: -144 | D19: 72 | E19: -12 | F19: 108 | G19: 405 | H19: 22 | I19: 75 | J19: 11 | K19: 153
A20: Power and Fuel | B20: 309 | C20: 295 | D20: 295 | E20: 308 | F20: 299 | G20: 339 | H20: 318 | I20: 384 | J20: 446 | K20: 427
A21: Other Mfr. Exp | B21: 2966 | C21: 2887 | D21: 2998 | E21: 3041 | F21: 2906 | G21: 2868 | H21: 3354 | I21: 3791 | J21: 3385 | K21: 3834
A22: Employee Cost | B22: 1680 | C22: 1743 | D22: 1860 | E22: 1875 | F22: 1820 | G22: 2358 | H22: 2545 | I22: 2854 | J22: 3009 | K22: 3077
A23: Selling and admin | B23: 6741 | C23: 6689 | D23: 7252 | E23: 7796 | F23: 7620 | G23: 7906 | H23: 8164 | I23: 8785 | J23: 10780 | K23: 10693
A24: Other Expenses | B24: 1313 | C24: 1470 | D24: 1480 | E24: 1553 | F24: 1688 | G24: 2195 | H24: 2359 | I24: 2267 | J24: 2806 | K24: 3056
A25: Other Income | B25: 486 | C25: 606 | D25: 353 | E25: 322 | F25: 424 | G25: 170 | H25: 219 | I25: 448 | J25: 817 | K25: 1322
A26: Depreciation | B26: 353 | C26: 432 | D26: 520 | E26: 565 | F26: 1002 | G26: 1074 | H26: 1091 | I26: 1137 | J26: 1216 | K26: 1355
A27: Interest | B27: 17 | C27: 35 | D27: 26 | E27: 33 | F27: 118 | G27: 117 | H27: 106 | I27: 114 | J27: 334 | K27: 395
... A31: Dividend Amount | B31: 3456 | C31: 3672 | D31: 4320 | E31: 4752 | F31: 5400 | G31: 9517.5 | H31: 7990 | I31: 9165 | J31: 9870 | K31: 12455
A33: EBIDTA | B33: =SUM(B30,B29,B27,B26) -> 6396 | C33: =SUM(C30,C29,C27,C26) -> 6920 | D33: =SUM(D30,D29,D27,D26) -> 7839 | E33: =SUM(E30,E29,E27,E26) -> 9196 | F33: =SUM(F30,F29,F27,F26) -> 10277 | G33: =SUM(G30,G29,G27,G26) -> 11792 | H33: =SUM(H30,H29,H27,H26) -> 13063 | I33: =SUM(I30,I29,I27,I26) -> 14572 | ... K33: =SUM(K30,K29,K27,K26) -> 16143
A40: Quarters
A41: Report Date | B41: 45107 | C41: 45199 | D41: 45291 | E41: 45382 | F41: 45473 | G41: 45565 | H41: 45657 | I41: 45747 | J41: 45838 | K41: 45930
A42: Sales | B42: 15496 | C42: 15623 | D42: 15567 | E42: 15210 | F42: 15707 | G42: 15926 | H42: 15818 | I42: 15670 | J42: 16514 | K42: 16241
A43: Expenses | B43: 11832 | C43: 11828 | D43: 11902 | E43: 11675 | F43: 11965 | G43: 12139 | H43: 12123 | I43: 12052 | J43: 12797 | K43: 12515
A44: Other Income | B44: 146 | C44: 178 | D44: 184 | E44: 309 | F44: 209 | G44: 203 | H44: 740 | I44: 171 | J44: 74 | K44: 331
A45: Depreciation | B45: 286 | C45: 297 | D45: 313 | E45: 320 | F45: 329 | G45: 338 | H45: 341 | I45: 347 | J45: 361 | K45: 358
A46: Interest | B46: 50 | C46: 88 | D46: 91 | E46: 105 | F46: 93 | G46: 110 | H46: 112 | I46: 80 | J46: 127 | K46: 129
A47: Profit before tax | B47: 3474 | C47: 3588 | D47: 3445 | E47: 3419 | F47: 3529 | G47: 3542 | H47: 3982 | I47: 3362 | J47: 3303 | K47: 3570
A48: Tax | B48: 918 | C48: 931 | D48: 937 | E48: 858 | F48: 917 | G48: 947 | H48: 993 | I48: 887 | J48: 535 | K48: 876
A49: Net profit | B49: 2554 | C49: 2656 | D49: 2509 | E49: 2558 | F49: 2610 | G49: 2591 | H49: 2984 | I49: 2464 | J49: 2756 | K49: 2685
A50: Operating Profit | B50: 3664 | C50: 3795 | D50: 3665 | E50: 3535 | F50: 3742 | G50: 3787 | H50: 3695 | I50: 3618 | J50: 3717 | K50: 3726
A55: BALANCE SHEET
A56: Report Date | B56: 42460 | C56: 42825 | D56: 43190 | E56: 43555 | F56: 43921 | G56: 44286 | H56: 44651 | I56: 45016 | J56: 45382 | K56: 45747
A57: Equity Share Capital | B57: 216 | C57: 216 | D57: 216 | E57: 216 | F57: 216 | G57: 235 | H57: 235 | I57: 235 | J57: 235 | K57: 235
A58: Reserves | B58: 6357 | C58: 6528 | D58: 7065 | E58: 7651 | F58: 8013 | G58: 47439 | H58: 48826 | I58: 50069 | J58: 50983 | K58: 49167
A59: Borrowings | B59: 177 | C59: 277 | E59: 99 | H59: 1043 | I59: 1219 | J59: 1484 | K59: 1648
A60: Other Liabilities | B60: 8043 | C60: 8685 | D60: 10581 | E60: 10663 | F60: 11924 | G60: 21066 | H60: 20402 | I60: 21554 | J60: 25787 | K60: 28813
...

Sheet Historical FS
P1: =IFERROR(SUM(#REF!),0) -> 0
B2: ="Historical Financial Statements -"&'Data Sheet'!B1 -> Historical Financial Statements -HINDUSTAN UNILEVER LTD
B3: Years | C3: ='Data Sheet'!B16 -> 42460 | D3: ='Data Sheet'!C16 -> 42825 | E3: ='Data Sheet'!D16 -> 43190 | F3: ='Data Sheet'!E16 -> 43555 | G3: ='Data Sheet'!F16 -> 43921 | H3: ='Data Sheet'!G16 -> 44286 | I3: ='Data Sheet'!H16 -> 44651 | J3: ='Data Sheet'!I16 -> 45016 | ... L3: ='Data Sheet'!K16 -> 45747
A4: # | B4: Income Statement
B5: Sales | C5: =IFERROR('Data Sheet'!B17,0) -> 32186 | D5: =IFERROR('Data Sheet'!C17,0) -> 33162 | E5: =IFERROR('Data Sheet'!D17,0) -> 35545 | F5: =IFERROR('Data Sheet'!E17,0) -> 39310 | G5: =IFERROR('Data Sheet'!F17,0) -> 39783 | H5: =IFERROR('Data Sheet'!G17,0) -> 47028 | I5: =IFERROR('Data Sheet'!H17,0) -> 52446 | J5: =IFERROR('Data Sheet'!I17,0) -> 60580 | ... L5: =IFERROR('Data Sheet'!K17,0) -> 63121
B6: Sales Growth | C6: - | D6: =D5/C5-1 -> 0.030323743 | E6: =E5/D5-1 -> 0.071859357 | F6: =F5/E5-1 -> 0.10592207 | G6: =G5/F5-1 -> 0.012032562 | H6: =H5/G5-1 -> 0.18211296 | I6: =I5/H5-1 -> 0.11520796 | J6: =J5/I5-1 -> 0.15509286 | K6: =K5/J5-1 -> 0.021723341 | L6: =L5/K5-1 -> 0.019791263
B8: COGS | C8: =IFERROR(SUM('Data Sheet'!B18,'Data Sheet'!B20:B22)-1*'Data Sheet'!B19,0) -> 18222 | D8: =IFERROR(SUM('Data Sheet'!C18,'Data Sheet'!C20:C22)-1*'Data Sheet'!C19,0) -> 18675 | E8: =IFERROR(SUM('Data Sheet'!D18,'Data Sheet'!D20:D22)-1*'Data Sheet'!D19,0) -> 19314 | F8: =IFERROR(SUM('Data Sheet'!E18,'Data Sheet'!E20:E22)-1*'Data Sheet'!E19,0) -> 21081 | G8: =IFERROR(SUM('Data Sheet'!F18,'Data Sheet'!F20:F22)-1*'Data Sheet'!F19,0) -> 20614 | H8: =IFERROR(SUM('Data Sheet'!G18,'Data Sheet'!G20:G22)-1*'Data Sheet'!G19,0) -> 25301 | I8: =IFERROR(SUM('Data Sheet'!H18,'Data Sheet'!H20:H22)-1*'Data Sheet'!H19,0) -> 29066 | J8: =IFERROR(SUM('Data Sheet'!I18,'Data Sheet'!I20:I22)-1*'Data Sheet'!I19,0) -> 35381 | ... L8: =IFERROR(SUM('Data Sheet'!K18,'Data Sheet'!K20:K22)-1*'Data Sheet'!K19,0) -> 34529
B9: COGS % Sales | C9: =C8/C5 -> 0.56614677 | D9: =D8/D5 -> 0.56314456 | E9: =E8/E5 -> 0.54336756 | F9: =F8/F5 -> 0.53627576 | G9: =G8/G5 -> 0.51816102 | H9: =H8/H5 -> 0.53799864 | I9: =I8/I5 -> 0.55420814 | J9: =J8/J5 -> 0.58403764 | ... L9: =L8/L5 -> 0.54702872
B11: Gross Profit | C11: =C5-C8 -> 13964 | D11: =D5-D8 -> 14487 | E11: =E5-E8 -> 16231 | F11: =F5-F8 -> 18229 | G11: =G5-G8 -> 19169 | H11: =H5-H8 -> 21727 | I11: =I5-I8 -> 23380 | J11: =J5-J8 -> 25199 | ... L11: =L5-L8 -> 28592
B12: Gross Margin | C12: =C11/C5 -> 0.43385323 | D12: =D11/D5 -> 0.43685544 | E12: =E11/E5 -> 0.45663244 | F12: =F11/F5 -> 0.46372424 | G12: =G11/G5 -> 0.48183898 | H12: =H11/H5 -> 0.46200136 | I12: =I11/I5 -> 0.44579186 | J12: =J11/J5 -> 0.41596236 | ... L12: =L11/L5 -> 0.45297128
B14: Selling and General Expenses | C14: =IFERROR(SUM('Data Sheet'!B23:B24),0) -> 8054 | D14: =IFERROR(SUM('Data Sheet'!C23:C24),0) -> 8159 | E14: =IFERROR(SUM('Data Sheet'!D23:D24),0) -> 8732 | F14: =IFERROR(SUM('Data Sheet'!E23:E24),0) -> 9349 | G14: =IFERROR(SUM('Data Sheet'!F23:F24),0) -> 9308 | H14: =IFERROR(SUM('Data Sheet'!G23:G24),0) -> 10101 | I14: =IFERROR(SUM('Data Sheet'!H23:H24),0) -> 10523 | J14: =IFERROR(SUM('Data Sheet'!I23:I24),0) -> 11052 | ... L14: =IFERROR(SUM('Data Sheet'!K23:K24),0) -> 13749
B15: S&G Exp % Sales | C15: =C14/C5 -> 0.25023302 | D15: =D14/D5 -> 0.24603462 | E15: =E14/E5 -> 0.24566043 | F15: =F14/F5 -> 0.23782752 | G15: =G14/G5 -> 0.23396928 | H15: =H14/H5 -> 0.21478694 | I15: =I14/I5 -> 0.20064447 | J15: =J14/J5 -> 0.18243645 | ... L15: =L14/L5 -> 0.21781974
B17: EBITDA | C17: =C11-C14 -> 5910 | D17: =D11-D14 -> 6328 | E17: =E11-E14 -> 7499 | F17: =F11-F14 -> 8880 | G17: =G11-G14 -> 9861 | H17: =H11-H14 -> 11626 | I17: =I11-I14 -> 12857 | J17: =J11-J14 -> 14147 | ... L17: =L11-L14 -> 14843
B18: EBITDA Margins | C18: =C17/C5 -> 0.18362021 | D18: =D17/D5 -> 0.19082082 | E18: =E17/E5 -> 0.21097201 | F18: =F17/F5 -> 0.22589672 | G18: =G17/G5 -> 0.24786969 | H18: =H17/H5 -> 0.24721443 | I18: =I17/I5 -> 0.24514739 | J18: =J17/J5 -> 0.23352592 | ... L18: =L17/L5 -> 0.23515153
B20: Interest | C20: =IFERROR('Data Sheet'!B27,0) -> 17 | D20: =IFERROR('Data Sheet'!C27,0) -> 35 | E20: =IFERROR('Data Sheet'!D27,0) -> 26 | F20: =IFERROR('Data Sheet'!E27,0) -> 33 | G20: =IFERROR('Data Sheet'!F27,0) -> 118 | H20: =IFERROR('Data Sheet'!G27,0) -> 117 | I20: =IFERROR('Data Sheet'!H27,0) -> 106 | J20: =IFERROR('Data Sheet'!I27,0) -> 114 | ... L20: =IFERROR('Data Sheet'!K27,0) -> 395
B21: Interest % Sales | C21: =C20/C5 -> 0.00052817995 | D21: =D20/D5 -> 0.0010554249 | E21: =E20/E5 -> 0.00073146715 | F21: =F20/F5 -> 0.00083948105 | G21: =G20/G5 -> 0.002966091 | H21: =H20/H5 -> 0.0024878796 | I21: =I20/I5 -> 0.0020211265 | J21: =J20/J5 -> 0.0018818092 | ... L21: =L20/L5 -> 0.0062578223
B23: Depreciation | C23: =IFERROR('Data Sheet'!B26,0) -> 353 | D23: =IFERROR('Data Sheet'!C26,0) -> 432 | E23: =IFERROR('Data Sheet'!D26,0) -> 520 | F23: =IFERROR('Data Sheet'!E26,0) -> 565 | G23: =IFERROR('Data Sheet'!F26,0) -> 1002 | H23: =IFERROR('Data Sheet'!G26,0) -> 1074 | I23: =IFERROR('Data Sheet'!H26,0) -> 1091 | J23: =IFERROR('Data Sheet'!I26,0) -> 1137 | ... L23: =IFERROR('Data Sheet'!K26,0) -> 1355
B24: Depreciation % Sales | C24: =C23/C5 -> 0.010967501 | D24: =D23/D5 -> 0.013026959 | E24: =E23/E5 -> 0.014629343 | F24: =F23/F5 -> 0.014372933 | G24: =G23/G5 -> 0.025186638 | H24: =H23/H5 -> 0.022837459 | I24: =I23/I5 -> 0.020802349 | J24: =J23/J5 -> 0.01876857 | ... L24: =L23/L5 -> 0.021466707
B26: Earnings Before Tax | C26: =IFERROR(C17-SUM(C20,C23),0) -> 5540 | D26: =IFERROR(D17-SUM(D20,D23),0) -> 5861 | E26: =IFERROR(E17-SUM(E20,E23),0) -> 6953 | F26: =IFERROR(F17-SUM(F20,F23),0) -> 8282 | G26: =IFERROR(G17-SUM(G20,G23),0) -> 8741 | H26: =IFERROR(H17-SUM(H20,H23),0) -> 10435 | I26: =IFERROR(I17-SUM(I20,I23),0) -> 11660 | J26: =IFERROR(J17-SUM(J20,J23),0) -> 12896 | ... L26: =IFERROR(L17-SUM(L20,L23),0) -> 13093
B27: EBT % Sales | C27: =C26/C5 -> 0.17212453 | D27: =D26/D5 -> 0.17673844 | E27: =E26/E5 -> 0.1956112 | F27: =F26/F5 -> 0.2106843 | G27: =G26/G5 -> 0.21971696 | H27: =H26/H5 -> 0.22188909 | I27: =I26/I5 -> 0.22232391 | J27: =J26/J5 -> 0.21287554 | ... L27: =L26/L5 -> 0.20742701
B29: Tax | C29: =IFERROR('Data Sheet'!B29,0) -> 1875 | D29: =IFERROR('Data Sheet'!C29,0) -> 1977 | E29: =IFERROR('Data Sheet'!D29,0) -> 2079 | F29: =IFERROR('Data Sheet'!E29,0) -> 2544 | G29: =IFERROR('Data Sheet'!F29,0) -> 2409 | H29: =IFERROR('Data Sheet'!G29,0) -> 2606 | I29: =IFERROR('Data Sheet'!H29,0) -> 2987 | J29: =IFERROR('Data Sheet'!I29,0) -> 3201 | ... L29: =IFERROR('Data Sheet'!K29,0) -> 3744
B30: Effective Tax Rate | C30: =C29/C26 -> 0.33844765 | D30: =D29/D26 -> 0.33731445 | E30: =E29/E26 -> 0.29900762 | F30: =F29/F26 -> 0.30717218 | G30: =G29/G26 -> 0.27559776 | H30: =H29/H26 -> 0.24973646 | I30: =I29/I26 -> 0.25617496 | J30: =J29/J26 -> 0.2482165 | ... L30: =L29/L26 -> 0.28595433
B32: Net Profit | C32: =IFERROR(C26-C29,0) -> 3665 | D32: =IFERROR(D26-D29,0) -> 3884 | E32: =IFERROR(E26-E29,0) -> 4874 | F32: =IFERROR(F26-F29,0) -> 5738 | G32: =IFERROR(G26-G29,0) -> 6332 | H32: =IFERROR(H26-H29,0) -> 7829 | I32: =IFERROR(I26-I29,0) -> 8673 | J32: =IFERROR(J26-J29,0) -> 9695 | ... L32: =IFERROR(L26-L29,0) -> 9349
B33: Net Margins | C33: =C32/C5 -> 0.11386938 | D33: =D32/D5 -> 0.11712201 | E33: =E32/E5 -> 0.13712196 | F33: =F32/F5 -> 0.14596795 | G33: =G32/G5 -> 0.15916346 | H33: =H32/H5 -> 0.16647529 | I33: =I32/I5 -> 0.16537009 | J33: =J32/J5 -> 0.16003632 | ... L33: =L32/L5 -> 0.14811236
B35: No.of Equity Shares | C35: =IFERROR('Data Sheet'!B93,0) -> 216.39 | D35: =IFERROR('Data Sheet'!C93,0) -> 216.43 | E35: =IFERROR('Data Sheet'!D93,0) -> 216.45 | F35: =IFERROR('Data Sheet'!E93,0) -> 216.47 | G35: =IFERROR('Data Sheet'!F93,0) -> 216.48 | H35: =IFERROR('Data Sheet'!G93,0) -> 234.96 | I35: =IFERROR('Data Sheet'!H93,0) -> 234.96 | J35: =IFERROR('Data Sheet'!I93,0) -> 234.96 | ... L35: =IFERROR('Data Sheet'!K93,0) -> 234.96
B37: Earning Per Share | C37: =IFERROR(C32/C35,0) -> 16.937012 | D37: =IFERROR(D32/D35,0) -> 17.945756 | E37: =IFERROR(E32/E35,0) -> 22.517903 | F37: =IFERROR(F32/F35,0) -> 26.507137 | G37: =IFERROR(G32/G35,0) -> 29.249815 | H37: =IFERROR(H32/H35,0) -> 33.320565 | I37: =IFERROR(I32/I35,0) -> 36.912666 | J37: =IFERROR(J32/J35,0) -> 41.262343 | ... L37: =IFERROR(L32/L35,0) -> 39.789751
B38: EPS Growth % | D38: =IFERROR(D37/C37-1,0) -> 0.059558573 | E38: =IFERROR(E37/D37-1,0) -> 0.25477591 | F38: =IFERROR(F37/E37-1,0) -> 0.17715836 | G38: =IFERROR(G37/F37-1,0) -> 0.10346941 | H38: =IFERROR(H37/G37-1,0) -> 0.13917182 | I38: =IFERROR(I37/H37-1,0) -> 0.10780432 | J38: =IFERROR(J37/I37-1,0) -> 0.11783697 | K38: =IFERROR(K37/J37-1,0) -> -0.023723569 | L38: =IFERROR(L37/K37-1,0) -> -0.012255679
B40: Dividend Per Share | C40: =IFERROR('Data Sheet'!B31/'Historical FS'!C35,0) -> 15.971163 | D40: =IFERROR('Data Sheet'!C31/'Historical FS'!D35,0) -> 16.966225 | E40: =IFERROR('Data Sheet'!D31/'Historical FS'!E35,0) -> 19.95842 | F40: =IFERROR('Data Sheet'!E31/'Historical FS'!F35,0) -> 21.952234 | G40: =IFERROR('Data Sheet'!F31/'Historical FS'!G35,0) -> 24.944568 | H40: =IFERROR('Data Sheet'!G31/'Historical FS'!H35,0) -> 40.506895 | I40: =IFERROR('Data Sheet'!H31/'Historical FS'!I35,0) -> 34.005788 | J40: =IFERROR('Data Sheet'!I31/'Historical FS'!J35,0) -> 39.006639 | ... L40: =IFERROR('Data Sheet'!K31/'Historical FS'!L35,0) -> 53.009023
B41: Dividend Payout Ratio | C41: =IFERROR(C40/C37,0) -> 0.94297408 | D41: =IFERROR(D40/D37,0) -> 0.9454171 | E41: =IFERROR(E40/E37,0) -> 0.88633566 | F41: =IFERROR(F40/F37,0) -> 0.82816312 | G41: =IFERROR(G40/G37,0) -> 0.85281112 | H41: =IFERROR(H40/H37,0) -> 1.2156725 | I41: =IFERROR(I40/I37,0) -> 0.92124986 | J41: =IFERROR(J40/J37,0) -> 0.94533265 | ... L41: =IFERROR(L40/L37,0) -> 1.332228
B43: Retained Earnings | C43: =IFERROR(1-C41,0) -> 0.057025921 | D43: =IFERROR(1-D41,0) -> 0.054582904 | E43: =IFERROR(1-E41,0) -> 0.11366434 | F43: =IFERROR(1-F41,0) -> 0.17183688 | G43: =IFERROR(1-G41,0) -> 0.14718888 | H43: =IFERROR(1-H41,0) -> -0.2156725 | I43: =IFERROR(1-I41,0) -> 0.078750144 | J43: =IFERROR(1-J41,0) -> 0.054667354 | ... L43: =IFERROR(1-L41,0) -> -0.33222805
A45: # | B45: Balance Sheet
B46: Equity Share Capital | C46: =IFERROR('Data Sheet'!B57,0) -> 216 | D46: =IFERROR('Data Sheet'!C57,0) -> 216 | E46: =IFERROR('Data Sheet'!D57,0) -> 216 | F46: =IFERROR('Data Sheet'!E57,0) -> 216 | G46: =IFERROR('Data Sheet'!F57,0) -> 216 | H46: =IFERROR('Data Sheet'!G57,0) -> 235 | I46: =IFERROR('Data Sheet'!H57,0) -> 235 | J46: =IFERROR('Data Sheet'!I57,0) -> 235 | ... L46: =IFERROR('Data Sheet'!K57,0) -> 235
B47: Reserves | C47: =IFERROR('Data Sheet'!B58,0) -> 6357 | D47: =IFERROR('Data Sheet'!C58,0) -> 6528 | E47: =IFERROR('Data Sheet'!D58,0) -> 7065 | F47: =IFERROR('Data Sheet'!E58,0) -> 7651 | G47: =IFERROR('Data Sheet'!F58,0) -> 8013 | H47: =IFERROR('Data Sheet'!G58,0) -> 47439 | I47: =IFERROR('Data Sheet'!H58,0) -> 48826 | J47: =IFERROR('Data Sheet'!I58,0) -> 50069 | ... L47: =IFERROR('Data Sheet'!K58,0) -> 49167
B48: Borrowings | C48: =IFERROR('Data Sheet'!B59,0) -> 177 | D48: =IFERROR('Data Sheet'!C59,0) -> 277 | E48: =IFERROR('Data Sheet'!D59,0) -> 0 | F48: =IFERROR('Data Sheet'!E59,0) -> 99 | G48: =IFERROR('Data Sheet'!F59,0) -> 0 | H48: =IFERROR('Data Sheet'!G59,0) -> 0 | I48: =IFERROR('Data Sheet'!H59,0) -> 1043 | J48: =IFERROR('Data Sheet'!I59,0) -> 1219 | ... L48: =IFERROR('Data Sheet'!K59,0) -> 1648
B49: Other Liabilities | C49: =IFERROR('Data Sheet'!B60,0) -> 8043 | D49: =IFERROR('Data Sheet'!C60,0) -> 8685 | E49: =IFERROR('Data Sheet'!D60,0) -> 10581 | F49: =IFERROR('Data Sheet'!E60,0) -> 10663 | G49: =IFERROR('Data Sheet'!F60,0) -> 11924 | H49: =IFERROR('Data Sheet'!G60,0) -> 21066 | I49: =IFERROR('Data Sheet'!H60,0) -> 20402 | J49: =IFERROR('Data Sheet'!I60,0) -> 21554 | ... L49: =IFERROR('Data Sheet'!K60,0) -> 28813
B50: Total Liabilites | C50: =IFERROR('Data Sheet'!B61,0) -> 14793 | D50: =IFERROR('Data Sheet'!C61,0) -> 15706 | E50: =IFERROR('Data Sheet'!D61,0) -> 17862 | F50: =IFERROR('Data Sheet'!E61,0) -> 18629 | G50: =IFERROR('Data Sheet'!F61,0) -> 20153 | H50: =IFERROR('Data Sheet'!G61,0) -> 68740 | I50: =IFERROR('Data Sheet'!H61,0) -> 70506 | J50: =IFERROR('Data Sheet'!I61,0) -> 73077 | ... L50: =IFERROR('Data Sheet'!K61,0) -> 79863
B52: Net Block | C52: =IFERROR('Data Sheet'!B62,0) -> 3258 | D52: =IFERROR('Data Sheet'!C62,0) -> 4419 | E52: =IFERROR('Data Sheet'!D62,0) -> 4528 | F52: =IFERROR('Data Sheet'!E62,0) -> 4715 | G52: =IFERROR('Data Sheet'!F62,0) -> 5479 | H52: =IFERROR('Data Sheet'!G62,0) -> 51443 | I52: =IFERROR('Data Sheet'!H62,0) -> 51473 | J52: =IFERROR('Data Sheet'!I62,0) -> 52678 | ... L52: =IFERROR('Data Sheet'!K62,0) -> 54335
B53: Capital Work in Progress | C53: =IFERROR('Data Sheet'!B63,0) -> 408 | D53: =IFERROR('Data Sheet'!C63,0) -> 229 | E53: =IFERROR('Data Sheet'!D63,0) -> 461 | F53: =IFERROR('Data Sheet'!E63,0) -> 406 | G53: =IFERROR('Data Sheet'!F63,0) -> 597 | H53: =IFERROR('Data Sheet'!G63,0) -> 745 | I53: =IFERROR('Data Sheet'!H63,0) -> 1313 | J53: =IFERROR('Data Sheet'!I63,0) -> 1132 | ... L53: =IFERROR('Data Sheet'!K63,0) -> 1009
B54: Investments | C54: =IFERROR('Data Sheet'!B64,0) -> 2592 | D54: =IFERROR('Data Sheet'!C64,0) -> 3794 | E54: =IFERROR('Data Sheet'!D64,0) -> 2873 | F54: =IFERROR('Data Sheet'!E64,0) -> 2716 | G54: =IFERROR('Data Sheet'!F64,0) -> 1255 | H54: =IFERROR('Data Sheet'!G64,0) -> 2709 | I54: =IFERROR('Data Sheet'!H64,0) -> 3521 | J54: =IFERROR('Data Sheet'!I64,0) -> 2882 | ... L54: =IFERROR('Data Sheet'!K64,0) -> 3810
B55: Other Assets | C55: =IFERROR('Data Sheet'!B65-SUM('Data Sheet'!B67:B69),0) -> 1536 | D55: =IFERROR('Data Sheet'!C65-SUM('Data Sheet'!C67:C69),0) -> 1810 | E55: =IFERROR('Data Sheet'!D65-SUM('Data Sheet'!D67:D69),0) -> 2692 | F55: =IFERROR('Data Sheet'!E65-SUM('Data Sheet'!E67:E69),0) -> 2645 | G55: =IFERROR('Data Sheet'!F65-SUM('Data Sheet'!F67:F69),0) -> 3793 | H55: =IFERROR('Data Sheet'!G65-SUM('Data Sheet'!G67:G69),0) -> 4035 | I55: =IFERROR('Data Sheet'!H65-SUM('Data Sheet'!H67:H69),0) -> 4021 | J55: =IFERROR('Data Sheet'!I65-SUM('Data Sheet'!I67:I69),0) -> 4377 | ... L55: =IFERROR('Data Sheet'!K65-SUM('Data Sheet'!K67:K69),0) -> 8033
...

Sheet Ratio Analysis
B3: Years | C3: ='Data Sheet'!B16 -> 42460 | D3: ='Data Sheet'!C16 -> 42825 | E3: ='Data Sheet'!D16 -> 43190 | F3: ='Data Sheet'!E16 -> 43555 | G3: ='Data Sheet'!F16 -> 43921 | H3: ='Data Sheet'!G16 -> 44286 | I3: ='Data Sheet'!H16 -> 44651 | J3: ='Data Sheet'!I16 -> 45016 | ... L3: ='Data Sheet'!K16 -> 45747 | M3: Trend | N3: Mean | O3: Median
B5: SalesGrowth | D5: =IFERROR('Historical FS'!D6,0) -> 0.030323743 | E5: =IFERROR('Historical FS'!E6,0) -> 0.071859357 | F5: =IFERROR('Historical FS'!F6,0) -> 0.10592207 | G5: =IFERROR('Historical FS'!G6,0) -> 0.012032562 | H5: =IFERROR('Historical FS'!H6,0) -> 0.18211296 | I5: =IFERROR('Historical FS'!I6,0) -> 0.11520796 | J5: =IFERROR('Historical FS'!J6,0) -> 0.15509286 | K5: =IFERROR('Historical FS'!K6,0) -> 0.021723341 | L5: =IFERROR('Historical FS'!L6,0) -> 0.019791263 | N5: =IFERROR(AVERAGE(D5:L5),0) -> 0.07934068 | O5: =IFERROR(MEDIAN(D5:L5),0) -> 0.071859357
B6: EBITDA Growth | D6: =IFERROR('Historical FS'!D17/'Historical FS'!C17-1,0) -> 0.07072758 | E6: =IFERROR('Historical FS'!E17/'Historical FS'!D17-1,0) -> 0.18505057 | F6: =IFERROR('Historical FS'!F17/'Historical FS'!E17-1,0) -> 0.18415789 | G6: =IFERROR('Historical FS'!G17/'Historical FS'!F17-1,0) -> 0.11047297 | H6: =IFERROR('Historical FS'!H17/'Historical FS'!G17-1,0) -> 0.17898793 | I6: =IFERROR('Historical FS'!I17/'Historical FS'!H17-1,0) -> 0.10588336 | J6: =IFERROR('Historical FS'!J17/'Historical FS'!I17-1,0) -> 0.10033445 | K6: =IFERROR('Historical FS'!K17/'Historical FS'!J17-1,0) -> 0.036191419 | L6: =IFERROR('Historical FS'!L17/'Historical FS'!K17-1,0) -> 0.012552016 | N6: =IFERROR(AVERAGE(D6:L6),0) -> 0.10937313 | O6: =IFERROR(MEDIAN(D6:L6),0) -> 0.10588336
B7: EBIT Growth | D7: =IFERROR('Historical FS'!D26/'Historical FS'!C26-1,0) -> 0.057942238 | E7: =IFERROR('Historical FS'!E26/'Historical FS'!D26-1,0) -> 0.18631633 | F7: =IFERROR('Historical FS'!F26/'Historical FS'!E26-1,0) -> 0.19114051 | G7: =IFERROR('Historical FS'!G26/'Historical FS'!F26-1,0) -> 0.055421396 | H7: =IFERROR('Historical FS'!H26/'Historical FS'!G26-1,0) -> 0.19379934 | I7: =IFERROR('Historical FS'!I26/'Historical FS'!H26-1,0) -> 0.11739339 | J7: =IFERROR('Historical FS'!J26/'Historical FS'!I26-1,0) -> 0.10600343 | K7: =IFERROR('Historical FS'!K26/'Historical FS'!J26-1,0) -> 0.016516749 | L7: =IFERROR('Historical FS'!L26/'Historical FS'!K26-1,0) -> -0.0012205355 | N7: =IFERROR(AVERAGE(D7:L7),0) -> 0.10259032 | O7: =IFERROR(MEDIAN(D7:L7),0) -> 0.10600343
B8: Net Profit Growth | D8: =IFERROR('Historical FS'!D32/'Historical FS'!C32-1,0) -> 0.059754434 | E8: =IFERROR('Historical FS'!E32/'Historical FS'!D32-1,0) -> 0.25489186 | F8: =IFERROR('Historical FS'!F32/'Historical FS'!E32-1,0) -> 0.17726713 | G8: =IFERROR('Historical FS'!G32/'Historical FS'!F32-1,0) -> 0.10352039 | H8: =IFERROR('Historical FS'!H32/'Historical FS'!G32-1,0) -> 0.23641819 | I8: =IFERROR('Historical FS'!I32/'Historical FS'!H32-1,0) -> 0.10780432 | J8: =IFERROR('Historical FS'!J32/'Historical FS'!I32-1,0) -> 0.11783697 | K8: =IFERROR('Historical FS'!K32/'Historical FS'!J32-1,0) -> -0.023723569 | L8: =IFERROR('Historical FS'!L32/'Historical FS'!K32-1,0) -> -0.012255679 | N8: =IFERROR(AVERAGE(D8:L8),0) -> 0.11350156 | O8: =IFERROR(MEDIAN(D8:L8),0) -> 0.10780432
B9: Dividend Growth | D9: =IFERROR('Historical FS'!D40/'Historical FS'!C40-1,0) -> 0.062303632 | E9: =IFERROR('Historical FS'!E40/'Historical FS'!D40-1,0) -> 0.17636188 | F9: =IFERROR('Historical FS'!F40/'Historical FS'!E40-1,0) -> 0.099898369 | G9: =IFERROR('Historical FS'!G40/'Historical FS'!F40-1,0) -> 0.13631114 | H9: =IFERROR('Historical FS'!H40/'Historical FS'!G40-1,0) -> 0.6238764 | I9: =IFERROR('Historical FS'!I40/'Historical FS'!H40-1,0) -> -0.16049383 | J9: =IFERROR('Historical FS'!J40/'Historical FS'!I40-1,0) -> 0.14705882 | K9: =IFERROR('Historical FS'!K40/'Historical FS'!J40-1,0) -> 0.076923077 | L9: =IFERROR('Historical FS'!L40/'Historical FS'!K40-1,0) -> 0.26190476 | N9: =IFERROR(AVERAGE(D9:L9),0) -> 0.15823825 | O9: =IFERROR(MEDIAN(D9:L9),0) -> 0.13631114
B11: Gross Margin | C11: =IFERROR('Historical FS'!C12,0) -> 0.43385323 | D11: =IFERROR('Historical FS'!D12,0) -> 0.43685544 | E11: =IFERROR('Historical FS'!E12,0) -> 0.45663244 | F11: =IFERROR('Historical FS'!F12,0) -> 0.46372424 | G11: =IFERROR('Historical FS'!G12,0) -> 0.48183898 | H11: =IFERROR('Historical FS'!H12,0) -> 0.46200136 | I11: =IFERROR('Historical FS'!I12,0) -> 0.44579186 | J11: =IFERROR('Historical FS'!J12,0) -> 0.41596236 | ... L11: =IFERROR('Historical FS'!L12,0) -> 0.45297128 | N11: =IFERROR(AVERAGE(C11:L11),0) -> 0.45059612 | O11: =IFERROR(MEDIAN(C11:L11),0) -> 0.45465063
B12: EBITDA Margin | C12: =IFERROR('Historical FS'!C18,0) -> 0.18362021 | D12: =IFERROR('Historical FS'!D18,0) -> 0.19082082 | E12: =IFERROR('Historical FS'!E18,0) -> 0.21097201 | F12: =IFERROR('Historical FS'!F18,0) -> 0.22589672 | G12: =IFERROR('Historical FS'!G18,0) -> 0.24786969 | H12: =IFERROR('Historical FS'!H18,0) -> 0.24721443 | I12: =IFERROR('Historical FS'!I18,0) -> 0.24514739 | J12: =IFERROR('Historical FS'!J18,0) -> 0.23352592 | ... L12: =IFERROR('Historical FS'!L18,0) -> 0.23515153 | N12: =IFERROR(AVERAGE(C12:L12),0) -> 0.22570515 | O12: =IFERROR(MEDIAN(C12:L12),0) -> 0.23433873
B13: EBIT Margin | C13: =IFERROR(('Historical FS'!C17-'Historical FS'!C23)/'Historical FS'!C5,0) -> 0.17265271 | D13: =IFERROR(('Historical FS'!D17-'Historical FS'!D23)/'Historical FS'!D5,0) -> 0.17779386 | E13: =IFERROR(('Historical FS'!E17-'Historical FS'!E23)/'Historical FS'!E5,0) -> 0.19634266 | F13: =IFERROR(('Historical FS'!F17-'Historical FS'!F23)/'Historical FS'!F5,0) -> 0.21152379 | G13: =IFERROR(('Historical FS'!G17-'Historical FS'!G23)/'Historical FS'!G5,0) -> 0.22268306 | H13: =IFERROR(('Historical FS'!H17-'Historical FS'!H23)/'Historical FS'!H5,0) -> 0.22437697 | I13: =IFERROR(('Historical FS'!I17-'Historical FS'!I23)/'Historical FS'!I5,0) -> 0.22434504 | J13: =IFERROR(('Historical FS'!J17-'Historical FS'!J23)/'Historical FS'!J5,0) -> 0.21475735 | ... L13: =IFERROR(('Historical FS'!L17-'Historical FS'!L23)/'Historical FS'!L5,0) -> 0.21368483 | N13: =IFERROR(AVERAGE(C13:L13),0) -> 0.20753471 | O13: =IFERROR(MEDIAN(C13:L13),0) -> 0.21422109
B14: EBT Margin | C14: =IFERROR('Historical FS'!C27,0) -> 0.17212453 | D14: =IFERROR('Historical FS'!D27,0) -> 0.17673844 | E14: =IFERROR('Historical FS'!E27,0) -> 0.1956112 | F14: =IFERROR('Historical FS'!F27,0) -> 0.2106843 | G14: =IFERROR('Historical FS'!G27,0) -> 0.21971696 | H14: =IFERROR('Historical FS'!H27,0) -> 0.22188909 | I14: =IFERROR('Historical FS'!I27,0) -> 0.22232391 | J14: =IFERROR('Historical FS'!J27,0) -> 0.21287554 | ... L14: =IFERROR('Historical FS'!L27,0) -> 0.20742701 | N14: =IFERROR(AVERAGE(C14:L14),0) -> 0.20511817 | O14: =IFERROR(MEDIAN(C14:L14),0) -> 0.21123753
B15: Net Profit Margin | C15: =IFERROR('Historical FS'!C33,0) -> 0.11386938 | D15: =IFERROR('Historical FS'!D33,0) -> 0.11712201 | E15: =IFERROR('Historical FS'!E33,0) -> 0.13712196 | F15: =IFERROR('Historical FS'!F33,0) -> 0.14596795 | G15: =IFERROR('Historical FS'!G33,0) -> 0.15916346 | H15: =IFERROR('Historical FS'!H33,0) -> 0.16647529 | I15: =IFERROR('Historical FS'!I33,0) -> 0.16537009 | J15: =IFERROR('Historical FS'!J33,0) -> 0.16003632 | ... L15: =IFERROR('Historical FS'!L33,0) -> 0.14811236 | N15: =IFERROR(AVERAGE(C15:L15),0) -> 0.14661566 | O15: =IFERROR(MEDIAN(C15:L15),0) -> 0.15051508
B17: SalesExpenses%Sales | C17: =IFERROR('Historical FS'!C15,0) -> 0.25023302 | D17: =IFERROR('Historical FS'!D15,0) -> 0.24603462 | E17: =IFERROR('Historical FS'!E15,0) -> 0.24566043 | F17: =IFERROR('Historical FS'!F15,0) -> 0.23782752 | G17: =IFERROR('Historical FS'!G15,0) -> 0.23396928 | H17: =IFERROR('Historical FS'!H15,0) -> 0.21478694 | I17: =IFERROR('Historical FS'!I15,0) -> 0.20064447 | J17: =IFERROR('Historical FS'!J15,0) -> 0.18243645 | ... L17: =IFERROR('Historical FS'!L15,0) -> 0.21781974 | N17: =IFERROR(AVERAGE(C17:L17),0) -> 0.22489097 | O17: =IFERROR(MEDIAN(C17:L17),0) -> 0.22673325
B18: Depreciation%Sales | C18: =IFERROR('Historical FS'!C24,0) -> 0.010967501 | D18: =IFERROR('Historical FS'!D24,0) -> 0.013026959 | E18: =IFERROR('Historical FS'!E24,0) -> 0.014629343 | F18: =IFERROR('Historical FS'!F24,0) -> 0.014372933 | G18: =IFERROR('Historical FS'!G24,0) -> 0.025186638 | H18: =IFERROR('Historical FS'!H24,0) -> 0.022837459 | I18: =IFERROR('Historical FS'!I24,0) -> 0.020802349 | J18: =IFERROR('Historical FS'!J24,0) -> 0.01876857 | ... L18: =IFERROR('Historical FS'!L24,0) -> 0.021466707 | N18: =IFERROR(AVERAGE(C18:L18),0) -> 0.018170432 | O18: =IFERROR(MEDIAN(C18:L18),0) -> 0.019207214
B19: OperatingIncome%Sales | C19: =IFERROR(C13,0) -> 0.17265271 | D19: =IFERROR(D13,0) -> 0.17779386 | E19: =IFERROR(E13,0) -> 0.19634266 | F19: =IFERROR(F13,0) -> 0.21152379 | G19: =IFERROR(G13,0) -> 0.22268306 | H19: =IFERROR(H13,0) -> 0.22437697 | I19: =IFERROR(I13,0) -> 0.22434504 | J19: =IFERROR(J13,0) -> 0.21475735 | ... L19: =IFERROR(L13,0) -> 0.21368483 | N19: =IFERROR(AVERAGE(C19:L19),0) -> 0.20753471 | O19: =IFERROR(MEDIAN(C19:L19),0) -> 0.21422109
B21: Return on Capital Employed | C21: =IFERROR(('Historical FS'!C17-'Historical FS'!C23)/(SUM('Historical FS'!C46:C48)),0) -> 0.82325926 | D21: =IFERROR(('Historical FS'!D17-'Historical FS'!D23)/(SUM('Historical FS'!D46:D48)),0) -> 0.83976642 | E21: =IFERROR(('Historical FS'!E17-'Historical FS'!E23)/(SUM('Historical FS'!E46:E48)),0) -> 0.95852218 | F21: =IFERROR(('Historical FS'!F17-'Historical FS'!F23)/(SUM('Historical FS'!F46:F48)),0) -> 1.0438112 | G21: =IFERROR(('Historical FS'!G17-'Historical FS'!G23)/(SUM('Historical FS'!G46:G48)),0) -> 1.0765585 | H21: =IFERROR(('Historical FS'!H17-'Historical FS'!H23)/(SUM('Historical FS'!H46:H48)),0) -> 0.22133658 | I21: =IFERROR(('Historical FS'!I17-'Historical FS'!I23)/(SUM('Historical FS'!I46:I48)),0) -> 0.23483155 | J21: =IFERROR(('Historical FS'!J17-'Historical FS'!J23)/(SUM('Historical FS'!J46:J48)),0) -> 0.25250859 | ... L21: =IFERROR(('Historical FS'!L17-'Historical FS'!L23)/(SUM('Historical FS'!L46:L48)),0) -> 0.26421156 | N21: =IFERROR(AVERAGE(C21:L21),0) -> 0.59698815 | O21: =IFERROR(MEDIAN(C21:L21),0) -> 0.54373541
B22: Retained Earnings% | C22: ='Historical FS'!C43 -> 0.057025921 | D22: ='Historical FS'!D43 -> 0.054582904 | E22: ='Historical FS'!E43 -> 0.11366434 | F22: ='Historical FS'!F43 -> 0.17183688 | G22: ='Historical FS'!G43 -> 0.14718888 | H22: ='Historical FS'!H43 -> -0.2156725 | I22: ='Historical FS'!I43 -> 0.078750144 | J22: ='Historical FS'!J43 -> 0.054667354 | ... L22: ='Historical FS'!L43 -> -0.33222805 | N22: =IFERROR(AVERAGE(C22:L22),0) -> 0.0087026655 | O22: =IFERROR(MEDIAN(C22:L22),0) -> 0.055846638
B23: Return on Equity% | C23: =IFERROR('Historical FS'!C32/SUM('Historical FS'!C46:C47),0) -> 0.55758406 | D23: =IFERROR('Historical FS'!D32/SUM('Historical FS'!D46:D47),0) -> 0.57591934 | E23: =IFERROR('Historical FS'!E32/SUM('Historical FS'!E46:E47),0) -> 0.66941354 | F23: =IFERROR('Historical FS'!F32/SUM('Historical FS'!F46:F47),0) -> 0.72937587 | G23: =IFERROR('Historical FS'!G32/SUM('Historical FS'!G46:G47),0) -> 0.76947381 | H23: =IFERROR('Historical FS'!H32/SUM('Historical FS'!H46:H47),0) -> 0.16421949 | I23: =IFERROR('Historical FS'!I32/SUM('Historical FS'!I46:I47),0) -> 0.17677993 | J23: =IFERROR('Historical FS'!J32/SUM('Historical FS'!J46:J47),0) -> 0.19272821 | ... L23: =IFERROR('Historical FS'!L32/SUM('Historical FS'!L46:L47),0) -> 0.18924335 | N23: =IFERROR(AVERAGE(C23:L23),0) -> 0.42095359 | O23: =IFERROR(MEDIAN(C23:L23),0) -> 0.37515613
B24: Self Sustained Growth Rate | C24: =IFERROR(C22*C23,0) -> 0.031796744 | D24: =IFERROR(D22*D23,0) -> 0.03143535 | E24: =IFERROR(E22*E23,0) -> 0.076088449 | F24: =IFERROR(F22*F23,0) -> 0.12533367 | G24: =IFERROR(G22*G23,0) -> 0.11325799 | H24: =IFERROR(H22*H23,0) -> -0.035417628 | I24: =IFERROR(I22*I23,0) -> 0.013921445 | J24: =IFERROR(J22*J23,0) -> 0.010535941 | ... L24: =IFERROR(L22*L23,0) -> -0.062871949 | N24: =IFERROR(AVERAGE(C24:L24),0) -> 0.029617264 | O24: =IFERROR(MEDIAN(C24:L24),0) -> 0.022678397
B25: Interest Coverage Ratio | C25: =(('Historical FS'!C17-'Historical FS'!C23)/'Historical FS'!C20) -> 326.88235 | D25: =(('Historical FS'!D17-'Historical FS'!D23)/'Historical FS'!D20) -> 168.45714 | E25: =(('Historical FS'!E17-'Historical FS'!E23)/'Historical FS'!E20) -> 268.42308 | F25: =(('Historical FS'!F17-'Historical FS'!F23)/'Historical FS'!F20) -> 251.9697 | G25: =(('Historical FS'!G17-'Historical FS'!G23)/'Historical FS'!G20) -> 75.076271 | H25: =(('Historical FS'!H17-'Historical FS'!H23)/'Historical FS'!H20) -> 90.188034 | I25: =(('Historical FS'!I17-'Historical FS'!I23)/'Historical FS'!I20) -> 111 | J25: =(('Historical FS'!J17-'Historical FS'!J23)/'Historical FS'!J20) -> 114.12281 | ... L25: =(('Historical FS'!L17-'Historical FS'!L23)/'Historical FS'!L20) -> 34.146835 | N25: =IFERROR(AVERAGE(C25:L25),0) -> 148.05147 | O25: =IFERROR(MEDIAN(C25:L25),0) -> 112.5614
B27: Debtor Turnover Ratio | C27: ='Historical FS'!C5/'Historical FS'!C58 -> 25.463608 | D27: ='Historical FS'!D5/'Historical FS'!D58 -> 30.564055 | E27: ='Historical FS'!E5/'Historical FS'!E58 -> 27.133588 | F27: ='Historical FS'!F5/'Historical FS'!F58 -> 21.646476 | G27: ='Historical FS'!G5/'Historical FS'!G58 -> 34.624021 | H27: ='Historical FS'!H5/'Historical FS'!H58 -> 26.750853 | I27: ='Historical FS'!I5/'Historical FS'!I58 -> 23.455277 | J27: ='Historical FS'!J5/'Historical FS'!J58 -> 19.675219 | ... L27: ='Historical FS'!L5/'Historical FS'!L58 -> 16.528149 | N27: =IFERROR(AVERAGE(C27:L27),0) -> 24.64939 | O27: =IFERROR(MEDIAN(C27:L27),0) -> 24.459442
B28: Creditor Turnover Ratio | C28: =IFERROR('Historical FS'!C5/'Historical FS'!C49,0) -> 4.0017406 | D28: =IFERROR('Historical FS'!D5/'Historical FS'!D49,0) -> 3.8183074 | E28: =IFERROR('Historical FS'!E5/'Historical FS'!E49,0) -> 3.3593233 | F28: =IFERROR('Historical FS'!F5/'Historical FS'!F49,0) -> 3.6865798 | G28: =IFERROR('Historical FS'!G5/'Historical FS'!G49,0) -> 3.3363804 | H28: =IFERROR('Historical FS'!H5/'Historical FS'!H49,0) -> 2.2324124 | I28: =IFERROR('Historical FS'!I5/'Historical FS'!I49,0) -> 2.5706303 | J28: =IFERROR('Historical FS'!J5/'Historical FS'!J49,0) -> 2.8106152 | ... L28: =IFERROR('Historical FS'!L5/'Historical FS'!L49,0) -> 2.1907125 | N28: =IFERROR(AVERAGE(C28:L28),0) -> 3.0406981 | O28: =IFERROR(MEDIAN(C28:L28),0) -> 3.0734978
B29: Inventory Turnover | C29: =IFERROR('Historical FS'!C5/'Historical FS'!C59,0) -> 11.807043 | D29: =IFERROR('Historical FS'!D5/'Historical FS'!D59,0) -> 13.050767 | E29: =IFERROR('Historical FS'!E5/'Historical FS'!E59,0) -> 14.144449 | F29: =IFERROR('Historical FS'!F5/'Historical FS'!F59,0) -> 15.27195 | G29: =IFERROR('Historical FS'!G5/'Historical FS'!G59,0) -> 14.377665 | H29: =IFERROR('Historical FS'!H5/'Historical FS'!H59,0) -> 13.139983 | I29: =IFERROR('Historical FS'!I5/'Historical FS'!I59,0) -> 12.804199 | J29: =IFERROR('Historical FS'!J5/'Historical FS'!J59,0) -> 14.250765 | ... L29: =IFERROR('Historical FS'!L5/'Historical FS'!L59,0) -> 14.296942 | N29: =IFERROR(AVERAGE(C29:L29),0) -> 13.853312 | O29: =IFERROR(MEDIAN(C29:L29),0) -> 14.197607
B30: Fixed Asset Turnover | C30: =IFERROR('Historical FS'!C5/'Historical FS'!C52,0) -> 9.8790669 | D30: =IFERROR('Historical FS'!D5/'Historical FS'!D52,0) -> 7.5044128 | E30: =IFERROR('Historical FS'!E5/'Historical FS'!E52,0) -> 7.8500442 | F30: =IFERROR('Historical FS'!F5/'Historical FS'!F52,0) -> 8.3372216 | G30: =IFERROR('Historical FS'!G5/'Historical FS'!G52,0) -> 7.2609965 | H30: =IFERROR('Historical FS'!H5/'Historical FS'!H52,0) -> 0.91417686 | I30: =IFERROR('Historical FS'!I5/'Historical FS'!I52,0) -> 1.0189031 | J30: =IFERROR('Historical FS'!J5/'Historical FS'!J52,0) -> 1.1500057 | ... L30: =IFERROR('Historical FS'!L5/'Historical FS'!L52,0) -> 1.1617006 | N30: =IFERROR(AVERAGE(C30:L30),0) -> 4.622821 | O30: =IFERROR(MEDIAN(C30:L30),0) -> 4.2113485
B31: Capital Turnover Ratio | C31: =IFERROR('Historical FS'!C5/SUM('Historical FS'!C46:C47),0) -> 4.8966986 | D31: =IFERROR('Historical FS'!D5/SUM('Historical FS'!D46:D47),0) -> 4.9172598 | E31: =IFERROR('Historical FS'!E5/SUM('Historical FS'!E46:E47),0) -> 4.8818844 | F31: =IFERROR('Historical FS'!F5/SUM('Historical FS'!F46:F47),0) -> 4.9968222 | G31: =IFERROR('Historical FS'!G5/SUM('Historical FS'!G46:G47),0) -> 4.8344878 | H31: =IFERROR('Historical FS'!H5/SUM('Historical FS'!H46:H47),0) -> 0.98644964 | I31: =IFERROR('Historical FS'!I5/SUM('Historical FS'!I46:I47),0) -> 1.0689957 | J31: =IFERROR('Historical FS'!J5/SUM('Historical FS'!J46:J47),0) -> 1.204278 | ... L31: =IFERROR('Historical FS'!L5/SUM('Historical FS'!L46:L47),0) -> 1.2777013 | N31: =IFERROR(AVERAGE(C31:L31),0) -> 3.0273059 | O31: =IFERROR(MEDIAN(C31:L31),0) -> 3.0560945
B33: (in days)
B34: Debtor Days | C34: =IFERROR(365/C27,0) -> 14.334183 | D34: =IFERROR(365/D27,0) -> 11.942133 | E34: =IFERROR(365/E27,0) -> 13.451962 | F34: =IFERROR(365/F27,0) -> 16.861867 | G34: =IFERROR(365/G27,0) -> 10.541814 | H34: =IFERROR(365/H27,0) -> 13.644425 | I34: =IFERROR(365/I27,0) -> 15.56153 | J34: =IFERROR(365/J27,0) -> 18.551255 | ... L34: =IFERROR(365/L27,0) -> 22.083538 | N34: =IFERROR(AVERAGE(C34:L34),0) -> 15.464598 | O34: =IFERROR(MEDIAN(C34:L34),0) -> 14.947856
B35: Payable Days | C35: =IFERROR(365/C28,0) -> 91.210309 | D35: =IFERROR(365/D28,0) -> 95.592093 | E35: =IFERROR(365/E28,0) -> 108.65283 | F35: =IFERROR(365/F28,0) -> 99.007759 | G35: =IFERROR(365/G28,0) -> 109.39999 | H35: =IFERROR(365/H28,0) -> 163.50026 | I35: =IFERROR(365/I28,0) -> 141.98852 | J35: =IFERROR(365/J28,0) -> 129.86481 | ... L35: =IFERROR(365/L28,0) -> 166.61246 | N35: =IFERROR(AVERAGE(C35:L35),0) -> 125.78947 | O35: =IFERROR(MEDIAN(C35:L35),0) -> 119.6324
B36: Inventory Days | C36: =IFERROR(365/C29,0) -> 30.913751 | D36: =IFERROR(365/D29,0) -> 27.967704 | E36: =IFERROR(365/E29,0) -> 25.805177 | F36: =IFERROR(365/F29,0) -> 23.900025 | G36: =IFERROR(365/G29,0) -> 25.386597 | H36: =IFERROR(365/H29,0) -> 27.777813 | I36: =IFERROR(365/I29,0) -> 28.506273 | J36: =IFERROR(365/J29,0) -> 25.612661 | ... L36: =IFERROR(365/L29,0) -> 25.529935 | N36: =IFERROR(AVERAGE(C36:L36),0) -> 26.511762 | O36: =IFERROR(MEDIAN(C36:L36),0) -> 25.708919
B37: Cash Conversion Cycle (in days) | C37: =SUM(C34,C36)-C35 -> -45.962375 | D37: =SUM(D34,D36)-D35 -> -55.682257 | E37: =SUM(E34,E36)-E35 -> -69.395696 | F37: =SUM(F34,F36)-F35 -> -58.245866 | G37: =SUM(G34,G36)-G35 -> -73.471583 | H37: =SUM(H34,H36)-H35 -> -122.07802 | I37: =SUM(I34,I36)-I35 -> -97.920718 | J37: =SUM(J34,J36)-J35 -> -85.700891 | ... L37: =SUM(L34,L36)-L35 -> -118.99899 | N37: =IFERROR(AVERAGE(C37:L37),0) -> -83.813107 | O37: =IFERROR(MEDIAN(C37:L37),0) -> -79.586237
B39: CFO/Sales | C39: =IFERROR('Historical FS'!C80/'Historical FS'!C5,0) -> 0.12707388 | D39: =IFERROR('Historical FS'!D80/'Historical FS'!D5,0) -> 0.17342139 | E39: =IFERROR('Historical FS'!E80/'Historical FS'!E5,0) -> 0.19397946 | F39: =IFERROR('Historical FS'!F80/'Historical FS'!F5,0) -> 0.13884508 | G39: =IFERROR('Historical FS'!G80/'Historical FS'!G5,0) -> 0.20194555 | H39: =IFERROR('Historical FS'!H80/'Historical FS'!H5,0) -> 0.19269371 | I39: =IFERROR('Historical FS'!I80/'Historical FS'!I5,0) -> 0.15345308 | J39: =IFERROR('Historical FS'!J80/'Historical FS'!J5,0) -> 0.1490756 | ... L39: =IFERROR('Historical FS'!L80/'Historical FS'!L5,0) -> 0.17582104 | N39: =IFERROR(AVERAGE(C39:L39),0) -> 0.1777441 | O39: =IFERROR(MEDIAN(C39:L39),0) -> 0.17462121
B40: CFO/Total Assets | C40: =IFERROR('Historical FS'!C80/'Historical FS'!C63,0) -> 0.27648212 | D40: =IFERROR('Historical FS'!D80/'Historical FS'!D63,0) -> 0.3661658 | E40: =IFERROR('Historical FS'!E80/'Historical FS'!E63,0) -> 0.386015 | F40: =IFERROR('Historical FS'!F80/'Historical FS'!F63,0) -> 0.29298406 | G40: =IFERROR('Historical FS'!G80/'Historical FS'!G63,0) -> 0.39865033 | H40: =IFERROR('Historical FS'!H80/'Historical FS'!H63,0) -> 0.13183008 | I40: =IFERROR('Historical FS'!I80/'Historical FS'!I63,0) -> 0.11414631 | J40: =IFERROR('Historical FS'!J80/'Historical FS'!J63,0) -> 0.12358198 | ... L40: =IFERROR('Historical FS'!L80/'Historical FS'!L63,0) -> 0.13896297 | N40: =IFERROR(AVERAGE(C40:L40),0) -> 0.24426321 | O40: =IFERROR(MEDIAN(C40:L40),0) -> 0.24514776
B41: CFO/Total Debt | C41: =IFERROR('Historical FS'!C80/'Historical FS'!C48,0) -> 23.107345 | D41: =IFERROR('Historical FS'!D80/'Historical FS'!D48,0) -> 20.761733 | E41: =IFERROR('Historical FS'!E80/'Historical FS'!E48,0) -> 0 | F41: =IFERROR('Historical FS'!F80/'Historical FS'!F48,0) -> 55.131313 | G41: =IFERROR('Historical FS'!G80/'Historical FS'!G48,0) -> 0 | H41: =IFERROR('Historical FS'!H80/'Historical FS'!H48,0) -> 0 | I41: =IFERROR('Historical FS'!I80/'Historical FS'!I48,0) -> 7.7162033 | J41: =IFERROR('Historical FS'!J80/'Historical FS'!J48,0) -> 7.4085316 | ... L41: =IFERROR('Historical FS'!L80/'Historical FS'!L48,0) -> 6.7342233 | N41: =IFERROR(AVERAGE(C41:L41),0) -> 13.216797 | O41: =IFERROR(MEDIAN(C41:L41),0) -> 7.5623674

Sheet Forecasting
B3: HUL LTD - Sales Forecasting | G3: HUL LTD - EBITDA Forecasting | L3: HUL LTD - Earning Per Share Forecasting
B4: Year Weight | C4: Year | D4: Sales | E4: Sales Growth | G4: Year Weight | H4: Year | I4: EBITDA | J4: EBITDA Growth | L4: Year Weight | M4: Year | N4: EPS | O4: EPS Growth
B5: 1 | C5: 2016 | D5: 32186 | G5: 1 | H5: 2016 | I5: ='Data Sheet'!B33 -> 6396 | L5: 1 | M5: 2016 | N5: {=TRANSPOSE('Historical FS'!C37:L37)} -> 16.937012
B6: =B5+1 -> 2 | C6: =C5+1 -> 2017 | D6: 33162 | E6: =D6/D5-1 -> 0.030323743 | G6: =G5+1 -> 2 | H6: =H5+1 -> 2017 | I6: ='Data Sheet'!C33 -> 6920 | J6: =I6/I5-1 -> 0.081926204 | L6: =L5+1 -> 2 | M6: =M5+1 -> 2017 | N6: 17.945756 | O6: =N6/N5-1 -> 0.059558573
B7: =B6+1 -> 3 | C7: =C6+1 -> 2018 | D7: 35545 | E7: =D7/D6-1 -> 0.071859357 | G7: =G6+1 -> 3 | H7: =H6+1 -> 2018 | I7: ='Data Sheet'!D33 -> 7839 | J7: =I7/I6-1 -> 0.13280347 | L7: =L6+1 -> 3 | M7: =M6+1 -> 2018 | N7: 22.517903 | O7: =N7/N6-1 -> 0.25477591
B8: =B7+1 -> 4 | C8: =C7+1 -> 2019 | D8: 39310 | E8: =D8/D7-1 -> 0.10592207 | G8: =G7+1 -> 4 | H8: =H7+1 -> 2019 | I8: ='Data Sheet'!E33 -> 9196 | J8: =I8/I7-1 -> 0.17310881 | L8: =L7+1 -> 4 | M8: =M7+1 -> 2019 | N8: 26.507137 | O8: =N8/N7-1 -> 0.17715836
B9: =B8+1 -> 5 | C9: =C8+1 -> 2020 | D9: 39783 | E9: =D9/D8-1 -> 0.012032562 | G9: =G8+1 -> 5 | H9: =H8+1 -> 2020 | I9: ='Data Sheet'!F33 -> 10277 | J9: =I9/I8-1 -> 0.11755111 | L9: =L8+1 -> 5 | M9: =M8+1 -> 2020 | N9: 29.249815 | O9: =N9/N8-1 -> 0.10346941
B10: =B9+1 -> 6 | C10: =C9+1 -> 2021 | D10: 47028 | E10: =D10/D9-1 -> 0.18211296 | G10: =G9+1 -> 6 | H10: =H9+1 -> 2021 | I10: ='Data Sheet'!G33 -> 11792 | J10: =I10/I9-1 -> 0.14741656 | L10: =L9+1 -> 6 | M10: =M9+1 -> 2021 | N10: 33.320565 | O10: =N10/N9-1 -> 0.13917182
